2020-03-07 13:39:14,507 - instabot version: 0.113.0 (bot) - INFO - Instabot version: 0.113.0 Started
2020-03-07 13:39:14,507 - instabot version: 0.113.0 (bot) - DEBUG - Bot imported from /Users/niels/Documents/instabot/examples/../instabot/bot/bot.py
2020-03-07 13:39:15,379 - instabot version: 0.113.0 (api_login) - INFO - Not yet logged in starting: PRE-LOGIN FLOW!
2020-03-07 13:39:15,918 - instabot version: 0.113.0 (api) - DEBUG - POST to endpoint: launcher/sync/ returned response: <Response [200]>
2020-03-07 13:39:16,428 - instabot version: 0.113.0 (api) - DEBUG - POST to endpoint: launcher/sync/ returned response: <Response [200]>
2020-03-07 13:39:17,256 - instabot version: 0.113.0 (api) - DEBUG - POST to endpoint: accounts/get_prefill_candidates/ returned response: <Response [200]>
2020-03-07 13:39:17,893 - instabot version: 0.113.0 (api) - DEBUG - POST to endpoint: qe/sync/ returned response: <Response [200]>
2020-03-07 13:39:19,656 - instabot version: 0.113.0 (api) - DEBUG - POST to endpoint: accounts/login/ returned response: <Response [200]>
2020-03-07 13:39:19,656 - instabot version: 0.113.0 (api) - INFO - Logged-in successfully as 'nielzdronepilot'!
2020-03-07 13:39:19,656 - instabot version: 0.113.0 (api_login) - INFO - LOGIN FLOW! Just logged-in: True
2020-03-07 13:39:20,239 - instabot version: 0.113.0 (api) - DEBUG - POST to endpoint: launcher/sync/ returned response: <Response [200]>
2020-03-07 13:39:20,778 - instabot version: 0.113.0 (api) - DEBUG - POST to endpoint: launcher/sync/ returned response: <Response [200]>
2020-03-07 13:39:20,780 - instabot version: 0.113.0 (api_login) - ERROR - Exception raised: '"type"'
Traceback (most recent call last):
  File "/Users/niels/Documents/instabot/examples/../instabot/api/api_login.py", line 147, in login_flow
    self.get_prefill_candidates(False)
  File "/Users/niels/Documents/instabot/examples/../instabot/api/api.py", line 171, in get_prefill_candidates
    return get_prefill_candidates(self, login)
  File "/Users/niels/Documents/instabot/examples/../instabot/api/api_login.py", line 78, in get_prefill_candidates
    data["client_contact_points"] = '{"type":"omnistring","value":"{}","source":"last_login_attempt"}'.format(self.username),
KeyError: '"type"'

2020-03-07 13:39:20,780 - instabot version: 0.113.0 (bot_checkpoint) - DEBUG - Loading Checkpoint file from: /Users/niels/Documents/instabot/examples/config/nielzdronepilot.checkpoint
2020-03-07 13:39:56,675 - instabot version: 0.113.0 (api) - DEBUG - POST to endpoint: accounts/logout/ returned response: <Response [200]>
2020-03-07 13:39:56,675 - instabot version: 0.113.0 (bot) - INFO - Bot stopped. Worked: 0:02:22.945690
2020-03-07 13:39:56,675 - instabot version: 0.113.0 (bot_checkpoint) - DEBUG - Saving Checkpoint file to: /Users/niels/Documents/instabot/examples/config/nielzdronepilot.checkpoint
2020-03-07 13:39:56,676 - instabot version: 0.113.0 (bot) - INFO - Total requests: 10
2020-03-07 13:39:56,676 - instabot version: 0.113.0 (bot_checkpoint) - DEBUG - Saving Checkpoint file to: /Users/niels/Documents/instabot/examples/config/nielzdronepilot.checkpoint
2020-03-07 13:39:56,676 - instabot version: 0.113.0 (bot) - INFO - Total requests: 10
